Workbook

Sheet Coded Responses
A1: ResponseId | B1: Response | C1: Issue(s) | D1: Action(s) | E1: Site-specific | F1: Goal(s) | G1: Goal - Theme - Subtheme
A2: R_5A0ewu3YjwrNabz | B2: Safty | C2: safety | E2: 0 | F2: Other | G2: Other
A3: R_7mOSK0wrthusCAu | B3: Housing | C3: housing | E3: 0 | F3: Other | G3: Other
A4: R_64fak4VghBVFjP3 | B4: Flooding | C4: flooding | E4: 0 | F4: Informed, engaged, and responsible community | G4: Informed, engaged, and responsible community - Climate change - Resilience
A5: R_3tDm3zEsgPxc7JU | B5: Clean air | C5: air quality | E5: 0 | F5: Clean waters and sediments | G5: Clean waters and sediments - Air quality
A6: R_5hFJ0BQNvGNSACR | B6: Rising rent | C6: rent | E6: 0 | F6: Other | G6: Other
A7: R_6Jk1MgREYShQTxp | B7: Homelessness | C7: homelessness | E7: 0 | F7: Other | G7: Other
A8: R_3rUGy48x7KOH453 | B8: Mental health | C8: mental health | E8: 0 | F8: Informed, engaged, and responsible community | G8: Informed, engaged, and responsible community - Well-being - Mental health
A9: R_7r814zaMjOI8Yil | B9: Pick up trash | C9: trash | D9: clean-up | E9: 0 | F9: Clean waters and sediments | G9: Clean waters and sediments - Water quality - Trash
A10: R_5Jn1DQDgLshPm3r | B10: Afford housing | C10: housing; affordability | E10: 0 | F10: Other | G10: Other
A11: R_5jSVCublUZLV517 | B11: leave no trace | C11: habitat degradation | D11: responsible use | E11: 0 | F11: Thriving habitats and abundant wildlife; Informed, engaged, and responsible community | G11: Thriving habitats and abundant wildlife - Habitats - Habitat degradation; Informed, engaged, and responsible community - Stewardship - Accountability
A12: R_1C0Wf9Ruk3Yv3SY | B12: Build more parks | C12: park | D12: build parks | E12: 0 | F12: Informed, engaged, and responsible community | G12: Informed, engaged, and responsible community - Recreation - Availability
A13: R_3QKNoG3yhVxak7Q | B13: eliminate toxins | C13: toxins | E13: 0 | F13: Clean waters and sediments | G13: Clean waters and sediments - Water quality
A14: R_1MWB4zOOGTBiMri | B14: Mow clean streets | C14: trash; streets | E14: 0 | F14: Clean waters and sediments | G14: Clean waters and sediments - Water quality - Trash
A15: R_5PREsAyG6utdLUe | B15: Stormwater runoff | C15: stormwater runoff | E15: 0 | F15: Clean waters and sediments | G15: Clean waters and sediments - Water quality - Stormwater
A16: R_1sYI0HAxB3rfdQd | B16: Bird Saunctuaries | C16: birds | D16: wildlife santuary | E16: 0 | F16: Thriving habitats and abundant wildlife | G16: Thriving habitats and abundant wildlife - Habitats - Habitat availability; Thriving habitats and abundant wildlife - Wildlife
A17: R_5fZ5yb6ypRI5mnK | B17: Energy consumption | C17: energy consumption | E17: 0 | F17: Informed, engaged, and responsible community | G17: Informed, engaged, and responsible community - Climate change - Sustainability
A18: R_6hG5lp8hSdUe50U | B18: Policial protection | D18: political protection | E18: 0 | F18: Informed, engaged, and responsible community | G18: Informed, engaged, and responsible community - Governance - Political influence
A19: R_6kWlmNr8fxkviut | B19: stop building roads | C19: streets; development | D19: limit development | E19: 0 | F19: Thriving habitats and abundant wildlife | G19: Thriving habitats and abundant wildlife - Land use - Development
A20: R_7I4zzuoblChqYrq | B20: important to protect | E20: 0
A21: R_3UapQqWMP30w6OU | B21: the recycling program | C21: trash | D21: recycling; program | E21: 0 | F21: Clean waters and sediments | G21: Clean waters and sediments - Water quality - Trash
A22: R_5D7GOKB5ek3VrqQ | B22: Bring people together | D22: bring people together | E22: 0 | F22: Informed, engaged, and responsible community | G22: Informed, engaged, and responsible community - Engagement - Involvement
A23: R_1lPIn7GiFtRE0Jd | B23: Lealman Park clean up | C23: trash | D23: clean-up | E23: 1 | F23: Clean waters and sediments | G23: Clean waters and sediments - Water quality - Trash
A24: R_51YDtwm2RIwn2sS | B24: Cleaning up the trash | C24: trash | D24: clean-up | E24: 0 | F24: Clean waters and sediments | G24: Clean waters and sediments - Water quality - Trash
A25: R_30ZDcjMqE8nWv37 | B25: Less litter everywhere | C25: trash | E25: 0 | F25: Clean waters and sediments | G25: Clean waters and sediments - Water quality - Trash
A26: R_30PCoyttQpvvp0x | B26: Cleaner drinking water | C26: drinking water quality | E26: 0 | F26: Clean waters and sediments | G26: Clean waters and sediments - Water quality - Drinking water
A27: R_78N9F3a5biAwUSB | B27: More beach protection. | C27: beach | E27: 0 | F27: Thriving habitats and abundant wildlife | G27: Thriving habitats and abundant wildlife - Habitats
A28: R_5DOyK43u0epJA5X | B28: Crime pollution poverty | C28: crime; poverty; pollution | E28: 0 | F28: Clean waters and sediments; Other | G28: Clean waters and sediments; Other
A29: R_6k0ohglwRkMf3Mq | B29: Development has to stop | C29: development | D29: limit development | E29: 0 | F29: Thriving habitats and abundant wildlife | G29: Thriving habitats and abundant wildlife - Land use - Development
A30: R_1HHpgiNsY7rKabu | B30: Helping protect wildlife | C30: wildlife | E30: 0 | F30: Thriving habitats and abundant wildlife | G30: Thriving habitats and abundant wildlife - Wildlife
A31: R_5nBCvZcicH9EKf6 | B31: Water pollution is huge! | C31: water pollution | E31: 0 | F31: Clean waters and sediments | G31: Clean waters and sediments - Water quality
A32: R_5JW8hO2AeAkePxh | B32: Protect the environment! | E32: 0
A33: R_6nPHPnuyRqHoVgg | B33: Cleaning the environment | D33: clean-up | E33: 0 | F33: Clean waters and sediments | G33: Clean waters and sediments - Water quality - Trash
A34: R_30cNCbhCi9HmOMl | B34: Keeping trash off beaches | C34: trash; beach | E34: 0 | F34: Clean waters and sediments; Thriving habitats and abundant wildlife | G34: Clean waters and sediments - Water quality - Trash; Thriving habitats and abundant wildlife - Habitats
A35: R_7p6hJKbOdSjeHXz | B35: The air in what we breath | C35: air quality | E35: 0 | F35: Clean waters and sediments | G35: Clean waters and sediments - Air quality
A36: R_6DbHkV8gf2oX4Jq | B36: Just make places cleaner. | C36: trash | E36: 0 | F36: Clean waters and sediments | G36: Clean waters and sediments - Water quality - Trash
A37: R_5w14vdY0PQ8uGUY | B37: Water supply Redevelopment | C37: water supply; redevelopment | E37: 0 | F37: Clean waters and sediments; Thriving habitats and abundant wildlife | G37: Clean waters and sediments - Water conservation - Water supply; Thriving habitats and abundant wildlife - Land use - Development
A38: R_1kNu6ipmpGBo3SR | B38: The homeless need shelter. | C38: homelessness | D38: homeless shelter | E38: 0 | F38: Other | G38: Other
A39: R_62bePviV0kPbEfu | B39: Trash and also homenessless | C39: trash; homelessness | E39: 0 | F39: Clean waters and sediments; Other | G39: Clean waters and sediments - Water quality - Trash; Other
A40: R_7WYyLRWEuPAm9tb | B40: More rec centers and fields | D40: recreational centers; recreational fields | E40: 0 | F40: Informed, engaged, and responsible community | G40: Informed, engaged, and responsible community - Recreation - Availability
...

Sheet Long Format
A1: ResponseId | B1: Goal | C1: Theme | D1: Subtheme | E1: First Goal Mentioned | F1: First Theme Mentioned
A2: R_5A0ewu3YjwrNabz | B2: Other | E2: =IF(COUNTIFS($A$2:A2,A2,$B$2:B2,B2)=1,1,0) -> 1 | F2: =IF(C2="",0,IF(COUNTIFS($A$2:A2,A2,$B$2:B2,B2,$C$2:C2,C2)=1,1,0)) -> 0
A3: R_7mOSK0wrthusCAu | B3: Other | E3: =IF(COUNTIFS($A$2:A3,A3,$B$2:B3,B3)=1,1,0) -> 1 | F3: =IF(C3="",0,IF(COUNTIFS($A$2:A3,A3,$B$2:B3,B3,$C$2:C3,C3)=1,1,0)) -> 0
A4: R_64fak4VghBVFjP3 | B4: Informed, engaged, and responsible community | C4: Climate change | D4: Resilience | E4: =IF(COUNTIFS($A$2:A4,A4,$B$2:B4,B4)=1,1,0) -> 1 | F4: =IF(C4="",0,IF(COUNTIFS($A$2:A4,A4,$B$2:B4,B4,$C$2:C4,C4)=1,1,0)) -> 1
A5: R_3tDm3zEsgPxc7JU | B5: Clean waters and sediments | C5: Air quality | E5: =IF(COUNTIFS($A$2:A5,A5,$B$2:B5,B5)=1,1,0) -> 1 | F5: =IF(C5="",0,IF(COUNTIFS($A$2:A5,A5,$B$2:B5,B5,$C$2:C5,C5)=1,1,0)) -> 1
A6: R_5hFJ0BQNvGNSACR | B6: Other | E6: =IF(COUNTIFS($A$2:A6,A6,$B$2:B6,B6)=1,1,0) -> 1 | F6: =IF(C6="",0,IF(COUNTIFS($A$2:A6,A6,$B$2:B6,B6,$C$2:C6,C6)=1,1,0)) -> 0
A7: R_6Jk1MgREYShQTxp | B7: Other | E7: =IF(COUNTIFS($A$2:A7,A7,$B$2:B7,B7)=1,1,0) -> 1 | F7: =IF(C7="",0,IF(COUNTIFS($A$2:A7,A7,$B$2:B7,B7,$C$2:C7,C7)=1,1,0)) -> 0
A8: R_3rUGy48x7KOH453 | B8: Informed, engaged, and responsible community | C8: Well-being | D8: Mental health | E8: =IF(COUNTIFS($A$2:A8,A8,$B$2:B8,B8)=1,1,0) -> 1 | F8: =IF(C8="",0,IF(COUNTIFS($A$2:A8,A8,$B$2:B8,B8,$C$2:C8,C8)=1,1,0)) -> 1
A9: R_7r814zaMjOI8Yil | B9: Clean waters and sediments | C9: Water quality | D9: Trash | E9: =IF(COUNTIFS($A$2:A9,A9,$B$2:B9,B9)=1,1,0) -> 1 | F9: =IF(C9="",0,IF(COUNTIFS($A$2:A9,A9,$B$2:B9,B9,$C$2:C9,C9)=1,1,0)) -> 1
A10: R_5Jn1DQDgLshPm3r | B10: Other | E10: =IF(COUNTIFS($A$2:A10,A10,$B$2:B10,B10)=1,1,0) -> 1 | F10: =IF(C10="",0,IF(COUNTIFS($A$2:A10,A10,$B$2:B10,B10,$C$2:C10,C10)=1,1,0)) -> 0
A11: R_5jSVCublUZLV517 | B11: Thriving habitats and abundant wildlife | C11: Habitats | D11: Habitat degradation | E11: =IF(COUNTIFS($A$2:A11,A11,$B$2:B11,B11)=1,1,0) -> 1 | F11: =IF(C11="",0,IF(COUNTIFS($A$2:A11,A11,$B$2:B11,B11,$C$2:C11,C11)=1,1,0)) -> 1
A12: R_5jSVCublUZLV517 | B12: Informed, engaged, and responsible community | C12: Stewardship | D12: Accountability | E12: =IF(COUNTIFS($A$2:A12,A12,$B$2:B12,B12)=1,1,0) -> 1 | F12: =IF(C12="",0,IF(COUNTIFS($A$2:A12,A12,$B$2:B12,B12,$C$2:C12,C12)=1,1,0)) -> 1
A13: R_1C0Wf9Ruk3Yv3SY | B13: Informed, engaged, and responsible community | C13: Recreation | D13: Availability | E13: =IF(COUNTIFS($A$2:A13,A13,$B$2:B13,B13)=1,1,0) -> 1 | F13: =IF(C13="",0,IF(COUNTIFS($A$2:A13,A13,$B$2:B13,B13,$C$2:C13,C13)=1,1,0)) -> 1
A14: R_3QKNoG3yhVxak7Q | B14: Clean waters and sediments | C14: Water quality | E14: =IF(COUNTIFS($A$2:A14,A14,$B$2:B14,B14)=1,1,0) -> 1 | F14: =IF(C14="",0,IF(COUNTIFS($A$2:A14,A14,$B$2:B14,B14,$C$2:C14,C14)=1,1,0)) -> 1
A15: R_1MWB4zOOGTBiMri | B15: Clean waters and sediments | C15: Water quality | D15: Trash | E15: =IF(COUNTIFS($A$2:A15,A15,$B$2:B15,B15)=1,1,0) -> 1 | F15: =IF(C15="",0,IF(COUNTIFS($A$2:A15,A15,$B$2:B15,B15,$C$2:C15,C15)=1,1,0)) -> 1
A16: R_5PREsAyG6utdLUe | B16: Clean waters and sediments | C16: Water quality | D16: Stormwater | E16: =IF(COUNTIFS($A$2:A16,A16,$B$2:B16,B16)=1,1,0) -> 1 | F16: =IF(C16="",0,IF(COUNTIFS($A$2:A16,A16,$B$2:B16,B16,$C$2:C16,C16)=1,1,0)) -> 1
A17: R_1sYI0HAxB3rfdQd | B17: Thriving habitats and abundant wildlife | C17: Habitats | D17: Habitat availability | E17: =IF(COUNTIFS($A$2:A17,A17,$B$2:B17,B17)=1,1,0) -> 1 | F17: =IF(C17="",0,IF(COUNTIFS($A$2:A17,A17,$B$2:B17,B17,$C$2:C17,C17)=1,1,0)) -> 1
A18: R_1sYI0HAxB3rfdQd | B18: Thriving habitats and abundant wildlife | C18: Wildlife | E18: =IF(COUNTIFS($A$2:A18,A18,$B$2:B18,B18)=1,1,0) -> 0 | F18: =IF(C18="",0,IF(COUNTIFS($A$2:A18,A18,$B$2:B18,B18,$C$2:C18,C18)=1,1,0)) -> 1
A19: R_5fZ5yb6ypRI5mnK | B19: Informed, engaged, and responsible community | C19: Climate change | D19: Sustainability | E19: =IF(COUNTIFS($A$2:A19,A19,$B$2:B19,B19)=1,1,0) -> 1 | F19: =IF(C19="",0,IF(COUNTIFS($A$2:A19,A19,$B$2:B19,B19,$C$2:C19,C19)=1,1,0)) -> 1
A20: R_6hG5lp8hSdUe50U | B20: Informed, engaged, and responsible community | C20: Governance | D20: Political influence | E20: =IF(COUNTIFS($A$2:A20,A20,$B$2:B20,B20)=1,1,0) -> 1 | F20: =IF(C20="",0,IF(COUNTIFS($A$2:A20,A20,$B$2:B20,B20,$C$2:C20,C20)=1,1,0)) -> 1
A21: R_6kWlmNr8fxkviut | B21: Thriving habitats and abundant wildlife | C21: Land use | D21: Development | E21: =IF(COUNTIFS($A$2:A21,A21,$B$2:B21,B21)=1,1,0) -> 1 | F21: =IF(C21="",0,IF(COUNTIFS($A$2:A21,A21,$B$2:B21,B21,$C$2:C21,C21)=1,1,0)) -> 1
A22: R_3UapQqWMP30w6OU | B22: Clean waters and sediments | C22: Water quality | D22: Trash | E22: =IF(COUNTIFS($A$2:A22,A22,$B$2:B22,B22)=1,1,0) -> 1 | F22: =IF(C22="",0,IF(COUNTIFS($A$2:A22,A22,$B$2:B22,B22,$C$2:C22,C22)=1,1,0)) -> 1
A23: R_5D7GOKB5ek3VrqQ | B23: Informed, engaged, and responsible community | C23: Engagement | D23: Involvement | E23: =IF(COUNTIFS($A$2:A23,A23,$B$2:B23,B23)=1,1,0) -> 1 | F23: =IF(C23="",0,IF(COUNTIFS($A$2:A23,A23,$B$2:B23,B23,$C$2:C23,C23)=1,1,0)) -> 1
A24: R_1lPIn7GiFtRE0Jd | B24: Clean waters and sediments | C24: Water quality | D24: Trash | E24: =IF(COUNTIFS($A$2:A24,A24,$B$2:B24,B24)=1,1,0) -> 1 | F24: =IF(C24="",0,IF(COUNTIFS($A$2:A24,A24,$B$2:B24,B24,$C$2:C24,C24)=1,1,0)) -> 1
A25: R_51YDtwm2RIwn2sS | B25: Clean waters and sediments | C25: Water quality | D25: Trash | E25: =IF(COUNTIFS($A$2:A25,A25,$B$2:B25,B25)=1,1,0) -> 1 | F25: =IF(C25="",0,IF(COUNTIFS($A$2:A25,A25,$B$2:B25,B25,$C$2:C25,C25)=1,1,0)) -> 1
A26: R_30ZDcjMqE8nWv37 | B26: Clean waters and sediments | C26: Water quality | D26: Trash | E26: =IF(COUNTIFS($A$2:A26,A26,$B$2:B26,B26)=1,1,0) -> 1 | F26: =IF(C26="",0,IF(COUNTIFS($A$2:A26,A26,$B$2:B26,B26,$C$2:C26,C26)=1,1,0)) -> 1
A27: R_30PCoyttQpvvp0x | B27: Clean waters and sediments | C27: Water quality | D27: Drinking water | E27: =IF(COUNTIFS($A$2:A27,A27,$B$2:B27,B27)=1,1,0) -> 1 | F27: =IF(C27="",0,IF(COUNTIFS($A$2:A27,A27,$B$2:B27,B27,$C$2:C27,C27)=1,1,0)) -> 1
A28: R_78N9F3a5biAwUSB | B28: Thriving habitats and abundant wildlife | C28: Habitats | E28: =IF(COUNTIFS($A$2:A28,A28,$B$2:B28,B28)=1,1,0) -> 1 | F28: =IF(C28="",0,IF(COUNTIFS($A$2:A28,A28,$B$2:B28,B28,$C$2:C28,C28)=1,1,0)) -> 1
A29: R_5DOyK43u0epJA5X | B29: Clean waters and sediments | E29: =IF(COUNTIFS($A$2:A29,A29,$B$2:B29,B29)=1,1,0) -> 1 | F29: =IF(C29="",0,IF(COUNTIFS($A$2:A29,A29,$B$2:B29,B29,$C$2:C29,C29)=1,1,0)) -> 0
A30: R_5DOyK43u0epJA5X | B30: Other | E30: =IF(COUNTIFS($A$2:A30,A30,$B$2:B30,B30)=1,1,0) -> 1 | F30: =IF(C30="",0,IF(COUNTIFS($A$2:A30,A30,$B$2:B30,B30,$C$2:C30,C30)=1,1,0)) -> 0
A31: R_6k0ohglwRkMf3Mq | B31: Thriving habitats and abundant wildlife | C31: Land use | D31: Development | E31: =IF(COUNTIFS($A$2:A31,A31,$B$2:B31,B31)=1,1,0) -> 1 | F31: =IF(C31="",0,IF(COUNTIFS($A$2:A31,A31,$B$2:B31,B31,$C$2:C31,C31)=1,1,0)) -> 1
A32: R_1HHpgiNsY7rKabu | B32: Thriving habitats and abundant wildlife | C32: Wildlife | E32: =IF(COUNTIFS($A$2:A32,A32,$B$2:B32,B32)=1,1,0) -> 1 | F32: =IF(C32="",0,IF(COUNTIFS($A$2:A32,A32,$B$2:B32,B32,$C$2:C32,C32)=1,1,0)) -> 1
A33: R_5nBCvZcicH9EKf6 | B33: Clean waters and sediments | C33: Water quality | E33: =IF(COUNTIFS($A$2:A33,A33,$B$2:B33,B33)=1,1,0) -> 1 | F33: =IF(C33="",0,IF(COUNTIFS($A$2:A33,A33,$B$2:B33,B33,$C$2:C33,C33)=1,1,0)) -> 1
A34: R_6nPHPnuyRqHoVgg | B34: Clean waters and sediments | C34: Water quality | D34: Trash | E34: =IF(COUNTIFS($A$2:A34,A34,$B$2:B34,B34)=1,1,0) -> 1 | F34: =IF(C34="",0,IF(COUNTIFS($A$2:A34,A34,$B$2:B34,B34,$C$2:C34,C34)=1,1,0)) -> 1
A35: R_30cNCbhCi9HmOMl | B35: Clean waters and sediments | C35: Water quality | D35: Trash | E35: =IF(COUNTIFS($A$2:A35,A35,$B$2:B35,B35)=1,1,0) -> 1 | F35: =IF(C35="",0,IF(COUNTIFS($A$2:A35,A35,$B$2:B35,B35,$C$2:C35,C35)=1,1,0)) -> 1
A36: R_30cNCbhCi9HmOMl | B36: Thriving habitats and abundant wildlife | C36: Habitats | E36: =IF(COUNTIFS($A$2:A36,A36,$B$2:B36,B36)=1,1,0) -> 1 | F36: =IF(C36="",0,IF(COUNTIFS($A$2:A36,A36,$B$2:B36,B36,$C$2:C36,C36)=1,1,0)) -> 1
A37: R_7p6hJKbOdSjeHXz | B37: Clean waters and sediments | C37: Air quality | E37: =IF(COUNTIFS($A$2:A37,A37,$B$2:B37,B37)=1,1,0) -> 1 | F37: =IF(C37="",0,IF(COUNTIFS($A$2:A37,A37,$B$2:B37,B37,$C$2:C37,C37)=1,1,0)) -> 1
A38: R_6DbHkV8gf2oX4Jq | B38: Clean waters and sediments | C38: Water quality | D38: Trash | E38: =IF(COUNTIFS($A$2:A38,A38,$B$2:B38,B38)=1,1,0) -> 1 | F38: =IF(C38="",0,IF(COUNTIFS($A$2:A38,A38,$B$2:B38,B38,$C$2:C38,C38)=1,1,0)) -> 1
A39: R_5w14vdY0PQ8uGUY | B39: Clean waters and sediments | C39: Water conservation | D39: Water supply | E39: =IF(COUNTIFS($A$2:A39,A39,$B$2:B39,B39)=1,1,0) -> 1 | F39: =IF(C39="",0,IF(COUNTIFS($A$2:A39,A39,$B$2:B39,B39,$C$2:C39,C39)=1,1,0)) -> 1
A40: R_5w14vdY0PQ8uGUY | B40: Thriving habitats and abundant wildlife | C40: Land use | D40: Development | E40: =IF(COUNTIFS($A$2:A40,A40,$B$2:B40,B40)=1,1,0) -> 1 | F40: =IF(C40="",0,IF(COUNTIFS($A$2:A40,A40,$B$2:B40,B40,$C$2:C40,C40)=1,1,0)) -> 1
...

Sheet Summary
A1: Coded responses (with at least one goal) | D1: =COUNTA('Coded Responses'!F2:F335) -> 317 | J1: Responses | K1: Percent of Responses
A2: Goal | B2: Theme | C2: Subtheme | D2: Responses | E2: % of coded responses | F2: Code assignments | I2: Clean waters and sediments | J2: =D3 -> 149 | K2: =J2/$D$1*100 -> 47.003155
A3: Clean waters and sediments | D3: =SUMIFS('Long Format'!$E$2:$E$642,'Long Format'!$B$2:$B$642,A3) -> 149 | E3: =IF($D$1=0,0,D3/$D$1) -> 0.47003155 | F3: =COUNTIFS('Long Format'!$B$2:$B$642,A3) -> 184 | I3: Thriving habitats and abundant wildlife | J3: =D17 -> 139 | K3: =J3/$D$1*100 -> 43.84858
A4: Clean waters and sediments | B4: Water quality | D4: =SUMIFS('Long Format'!$F$2:$F$642,'Long Format'!$B$2:$B$642,A4,'Long Format'!$C$2:$C$642,B4) -> 128 | E4: =IF($D$1=0,0,D4/$D$1) -> 0.40378549 | F4: =COUNTIFS('Long Format'!$B$2:$B$642,A4,'Long Format'!$C$2:$C$642,B4) -> 154 | I4: Informed, engaged, and responsible community | J4: =D30 -> 140 | K4: =J4/$D$1*100 -> 44.164038
A5: Clean waters and sediments | B5: Water quality | C5: Drinking water | F5: =COUNTIFS('Long Format'!$B$2:$B$642,A5,'Long Format'!$C$2:$C$642,B5,'Long Format'!$D$2:$D$642,C5) -> 6 | I5: Other | J5: =D57 -> 42 | K5: =J5/$D$1*100 -> 13.249211
A6: Clean waters and sediments | B6: Water quality | C6: Stormwater | F6: =COUNTIFS('Long Format'!$B$2:$B$642,A6,'Long Format'!$C$2:$C$642,B6,'Long Format'!$D$2:$D$642,C6) -> 17
A7: Clean waters and sediments | B7: Water quality | C7: Nutrients | F7: =COUNTIFS('Long Format'!$B$2:$B$642,A7,'Long Format'!$C$2:$C$642,B7,'Long Format'!$D$2:$D$642,C7) -> 21 | I7: Water quality | J7: =D4 -> 128 | K7: =J7/$J$2*100 -> 85.90604
A8: Clean waters and sediments | B8: Water quality | C8: Trash | F8: =COUNTIFS('Long Format'!$B$2:$B$642,A8,'Long Format'!$C$2:$C$642,B8,'Long Format'!$D$2:$D$642,C8) -> 59 | I8: Drinking water | J8: =F5 -> 6 | K8: =J8/$J$2*100 -> 4.0268456
A9: Clean waters and sediments | B9: Water quality | C9: (none) | F9: =COUNTIFS('Long Format'!$B$2:$B$642,A9,'Long Format'!$C$2:$C$642,B9,'Long Format'!$D$2:$D$642,"") -> 51 | I9: Stormwater | J9: =F6 -> 17 | K9: =J9/$J$2*100 -> 11.409396
A10: Clean waters and sediments | B10: Water conservation | D10: =SUMIFS('Long Format'!$F$2:$F$642,'Long Format'!$B$2:$B$642,A10,'Long Format'!$C$2:$C$642,B10) -> 18 | E10: =IF($D$1=0,0,D10/$D$1) -> 0.056782334 | F10: =COUNTIFS('Long Format'!$B$2:$B$642,A10,'Long Format'!$C$2:$C$642,B10) -> 18 | I10: Nutrients | J10: =F7 -> 21 | K10: =J10/$J$2*100 -> 14.09396
A11: Clean waters and sediments | B11: Water conservation | C11: Water use | F11: =COUNTIFS('Long Format'!$B$2:$B$642,A11,'Long Format'!$C$2:$C$642,B11,'Long Format'!$D$2:$D$642,C11) -> 7 | I11: Trash | J11: =F8 -> 59 | K11: =J11/$J$2*100 -> 39.597315
A12: Clean waters and sediments | B12: Water conservation | C12: Water supply | F12: =COUNTIFS('Long Format'!$B$2:$B$642,A12,'Long Format'!$C$2:$C$642,B12,'Long Format'!$D$2:$D$642,C12) -> 10 | I12: Water conservation | J12: =D10 -> 18 | K12: =J12/$J$2*100 -> 12.080537
A13: Clean waters and sediments | B13: Water conservation | C13: (none) | F13: =COUNTIFS('Long Format'!$B$2:$B$642,A13,'Long Format'!$C$2:$C$642,B13,'Long Format'!$D$2:$D$642,"") -> 1 | I13: Water use | J13: =F11 -> 7 | K13: =J13/$J$2*100 -> 4.6979866
A14: Clean waters and sediments | B14: Air quality | D14: =SUMIFS('Long Format'!$F$2:$F$642,'Long Format'!$B$2:$B$642,A14,'Long Format'!$C$2:$C$642,B14) -> 9 | E14: =IF($D$1=0,0,D14/$D$1) -> 0.028391167 | F14: =COUNTIFS('Long Format'!$B$2:$B$642,A14,'Long Format'!$C$2:$C$642,B14) -> 9 | I14: Water supply | J14: =F12 -> 10 | K14: =J14/$J$2*100 -> 6.7114094
A15: Clean waters and sediments | B15: Air quality | C15: (none) | F15: =COUNTIFS('Long Format'!$B$2:$B$642,A15,'Long Format'!$C$2:$C$642,B15,'Long Format'!$D$2:$D$642,"") -> 9 | I15: Air quality | J15: =D14 -> 9 | K15: =J15/$J$2*100 -> 6.0402685
A16: Clean waters and sediments | F16: =COUNTIFS('Long Format'!$B$2:$B$642,A16,'Long Format'!$C$2:$C$642,"") -> 3
A17: Thriving habitats and abundant wildlife | D17: =SUMIFS('Long Format'!$E$2:$E$642,'Long Format'!$B$2:$B$642,A17) -> 139 | E17: =IF($D$1=0,0,D17/$D$1) -> 0.4384858 | F17: =COUNTIFS('Long Format'!$B$2:$B$642,A17) -> 224
A18: Thriving habitats and abundant wildlife | B18: Habitats | D18: =SUMIFS('Long Format'!$F$2:$F$642,'Long Format'!$B$2:$B$642,A18,'Long Format'!$C$2:$C$642,B18) -> 84 | E18: =IF($D$1=0,0,D18/$D$1) -> 0.26498423 | F18: =COUNTIFS('Long Format'!$B$2:$B$642,A18,'Long Format'!$C$2:$C$642,B18) -> 94
A19: Thriving habitats and abundant wildlife | B19: Habitats | C19: Habitat degradation | F19: =COUNTIFS('Long Format'!$B$2:$B$642,A19,'Long Format'!$C$2:$C$642,B19,'Long Format'!$D$2:$D$642,C19) -> 28 | I19: Habitats | J19: =D18 -> 84 | K19: =J19/$J$3*100 -> 60.431655
A20: Thriving habitats and abundant wildlife | B20: Habitats | C20: Habitat loss | F20: =COUNTIFS('Long Format'!$B$2:$B$642,A20,'Long Format'!$C$2:$C$642,B20,'Long Format'!$D$2:$D$642,C20) -> 30 | I20: Habitat degradation | J20: =F19 -> 28 | K20: =J20/$J$3*100 -> 20.143885
A21: Thriving habitats and abundant wildlife | B21: Habitats | C21: Habitat availability | F21: =COUNTIFS('Long Format'!$B$2:$B$642,A21,'Long Format'!$C$2:$C$642,B21,'Long Format'!$D$2:$D$642,C21) -> 17 | I21: Habitat loss | J21: =F20 -> 30 | K21: =J21/$J$3*100 -> 21.582734
A22: Thriving habitats and abundant wildlife | B22: Habitats | C22: (none) | F22: =COUNTIFS('Long Format'!$B$2:$B$642,A22,'Long Format'!$C$2:$C$642,B22,'Long Format'!$D$2:$D$642,"") -> 19 | I22: Habitat availability | J22: =F21 -> 17 | K22: =J22/$J$3*100 -> 12.230216
A23: Thriving habitats and abundant wildlife | B23: Wildlife | D23: =SUMIFS('Long Format'!$F$2:$F$642,'Long Format'!$B$2:$B$642,A23,'Long Format'!$C$2:$C$642,B23) -> 75 | E23: =IF($D$1=0,0,D23/$D$1) -> 0.23659306 | F23: =COUNTIFS('Long Format'!$B$2:$B$642,A23,'Long Format'!$C$2:$C$642,B23) -> 77 | I23: Wildlife | J23: =D23 -> 75 | K23: =J23/$J$3*100 -> 53.956835
A24: Thriving habitats and abundant wildlife | B24: Wildlife | C24: Wildlife loss/safety | F24: =COUNTIFS('Long Format'!$B$2:$B$642,A24,'Long Format'!$C$2:$C$642,B24,'Long Format'!$D$2:$D$642,C24) -> 25 | I24: Wildlife loss/safety | J24: =F24 -> 25 | K24: =J24/$J$3*100 -> 17.985612
A25: Thriving habitats and abundant wildlife | B25: Wildlife | C25: Wildlife displacement | F25: =COUNTIFS('Long Format'!$B$2:$B$642,A25,'Long Format'!$C$2:$C$642,B25,'Long Format'!$D$2:$D$642,C25) -> 9 | I25: Wildlife displacement | J25: =F25 -> 9 | K25: =J25/$J$3*100 -> 6.4748201
A26: Thriving habitats and abundant wildlife | B26: Wildlife | C26: (none) | F26: =COUNTIFS('Long Format'!$B$2:$B$642,A26,'Long Format'!$C$2:$C$642,B26,'Long Format'!$D$2:$D$642,"") -> 43 | I26: Land use | J26: =D27 -> 53 | K26: =J26/$J$3*100 -> 38.129496
A27: Thriving habitats and abundant wildlife | B27: Land use | D27: =SUMIFS('Long Format'!$F$2:$F$642,'Long Format'!$B$2:$B$642,A27,'Long Format'!$C$2:$C$642,B27) -> 53 | E27: =IF($D$1=0,0,D27/$D$1) -> 0.16719243 | F27: =COUNTIFS('Long Format'!$B$2:$B$642,A27,'Long Format'!$C$2:$C$642,B27) -> 53 | I27: Development | J27: =F28 -> 52 | K27: =J27/$J$3*100 -> 37.410072
A28: Thriving habitats and abundant wildlife | B28: Land use | C28: Development | F28: =COUNTIFS('Long Format'!$B$2:$B$642,A28,'Long Format'!$C$2:$C$642,B28,'Long Format'!$D$2:$D$642,C28) -> 52
A29: Thriving habitats and abundant wildlife | B29: Land use | C29: (none) | F29: =COUNTIFS('Long Format'!$B$2:$B$642,A29,'Long Format'!$C$2:$C$642,B29,'Long Format'!$D$2:$D$642,"") -> 1
A30: Informed, engaged, and responsible community | D30: =SUMIFS('Long Format'!$E$2:$E$642,'Long Format'!$B$2:$B$642,A30) -> 140 | E30: =IF($D$1=0,0,D30/$D$1) -> 0.44164038 | F30: =COUNTIFS('Long Format'!$B$2:$B$642,A30) -> 191
A31: Informed, engaged, and responsible community | B31: Recreation | D31: =SUMIFS('Long Format'!$F$2:$F$642,'Long Format'!$B$2:$B$642,A31,'Long Format'!$C$2:$C$642,B31) -> 18 | E31: =IF($D$1=0,0,D31/$D$1) -> 0.056782334 | F31: =COUNTIFS('Long Format'!$B$2:$B$642,A31,'Long Format'!$C$2:$C$642,B31) -> 19 | I31: Recreation | J31: =D31 -> 18 | K31: =J31/$J$4*100 -> 12.857143
A32: Informed, engaged, and responsible community | B32: Recreation | C32: Availability | F32: =COUNTIFS('Long Format'!$B$2:$B$642,A32,'Long Format'!$C$2:$C$642,B32,'Long Format'!$D$2:$D$642,C32) -> 10 | I32: Availability | J32: =F32 -> 10 | K32: =J32/$J$4*100 -> 7.1428571
A33: Informed, engaged, and responsible community | B33: Recreation | C33: Accessibility | F33: =COUNTIFS('Long Format'!$B$2:$B$642,A33,'Long Format'!$C$2:$C$642,B33,'Long Format'!$D$2:$D$642,C33) -> 9 | I33: Accessibility | J33: =F33 -> 9 | K33: =J33/$J$4*100 -> 6.4285714
A34: Informed, engaged, and responsible community | B34: Recreation | C34: (none) | F34: =COUNTIFS('Long Format'!$B$2:$B$642,A34,'Long Format'!$C$2:$C$642,B34,'Long Format'!$D$2:$D$642,"") -> 0 | I34: Engagement | J34: =D45 -> 56 | K34: =J34/$J$4*100 -> 40
A35: Informed, engaged, and responsible community | B35: Well-being | D35: =SUMIFS('Long Format'!$F$2:$F$642,'Long Format'!$B$2:$B$642,A35,'Long Format'!$C$2:$C$642,B35) -> 17 | E35: =IF($D$1=0,0,D35/$D$1) -> 0.05362776 | F35: =COUNTIFS('Long Format'!$B$2:$B$642,A35,'Long Format'!$C$2:$C$642,B35) -> 17 | I35: Education | J35: =F46 -> 35 | K35: =J35/$J$4*100 -> 25
A36: Informed, engaged, and responsible community | B36: Well-being | C36: Safety | F36: =COUNTIFS('Long Format'!$B$2:$B$642,A36,'Long Format'!$C$2:$C$642,B36,'Long Format'!$D$2:$D$642,C36) -> 16 | I36: Involvement | J36: =F47 -> 29 | K36: =J36/$J$4*100 -> 20.714286
A37: Informed, engaged, and responsible community | B37: Well-being | C37: Mental health | F37: =COUNTIFS('Long Format'!$B$2:$B$642,A37,'Long Format'!$C$2:$C$642,B37,'Long Format'!$D$2:$D$642,C37) -> 1 | I37: Stewardship | J37: =D49 -> 20 | K37: =J37/$J$4*100 -> 14.285714
A38: Informed, engaged, and responsible community | B38: Well-being | C38: (none) | F38: =COUNTIFS('Long Format'!$B$2:$B$642,A38,'Long Format'!$C$2:$C$642,B38,'Long Format'!$D$2:$D$642,"") -> 0 | I38: Compliance | J38: =F50 -> 2 | K38: =J38/$J$4*100 -> 1.4285714
A39: Informed, engaged, and responsible community | B39: Governance | D39: =SUMIFS('Long Format'!$F$2:$F$642,'Long Format'!$B$2:$B$642,A39,'Long Format'!$C$2:$C$642,B39) -> 38 | E39: =IF($D$1=0,0,D39/$D$1) -> 0.11987382 | F39: =COUNTIFS('Long Format'!$B$2:$B$642,A39,'Long Format'!$C$2:$C$642,B39) -> 43 | I39: Accountability | J39: =F51 -> 18 | K39: =J39/$J$4*100 -> 12.857143
A40: Informed, engaged, and responsible community | B40: Governance | C40: Regulation | F40: =COUNTIFS('Long Format'!$B$2:$B$642,A40,'Long Format'!$C$2:$C$642,B40,'Long Format'!$D$2:$D$642,C40) -> 15 | I40: Governance | J40: =D39 -> 38 | K40: =J40/$J$4*100 -> 27.142857
...
